2018-07-15 21:24:42,414 ERROR: Exception on / [GET] [in c:\microblog\virtualenv\lib\site-packages\flask\app.py:1761]
Traceback (most recent call last):
  File "c:\microblog\virtualenv\lib\site-packages\flask\app.py", line 2292, in wsgi_app
    response = self.full_dispatch_request()
  File "c:\microblog\virtualenv\lib\site-packages\flask\app.py", line 1815, in full_dispatch_request
    rv = self.handle_user_exception(e)
  File "c:\microblog\virtualenv\lib\site-packages\flask\app.py", line 1718, in handle_user_exception
    reraise(exc_type, exc_value, tb)
  File "c:\microblog\virtualenv\lib\site-packages\flask\_compat.py", line 35, in reraise
    raise value
  File "c:\microblog\virtualenv\lib\site-packages\flask\app.py", line 1813, in full_dispatch_request
    rv = self.dispatch_request()
  File "c:\microblog\virtualenv\lib\site-packages\flask\app.py", line 1799, in dispatch_request
    return self.view_functions[rule.endpoint](**req.view_args)
  File "c:\microblog\virtualenv\lib\site-packages\flask_login\utils.py", line 261, in decorated_view
    return func(*args, **kwargs)
  File "C:\microblog\app\routes.py", line 42, in index
    return render_template('index.html',title='Home',form=form,posts=posts.items,prev_url=prev_url,next_url=next_url)
  File "c:\microblog\virtualenv\lib\site-packages\flask\templating.py", line 135, in render_template
    context, ctx.app)
  File "c:\microblog\virtualenv\lib\site-packages\flask\templating.py", line 117, in _render
    rv = template.render(context)
  File "c:\microblog\virtualenv\lib\site-packages\jinja2\asyncsupport.py", line 76, in render
    return original_render(self, *args, **kwargs)
  File "c:\microblog\virtualenv\lib\site-packages\jinja2\environment.py", line 1008, in render
    return self.environment.handle_exception(exc_info, True)
  File "c:\microblog\virtualenv\lib\site-packages\jinja2\environment.py", line 780, in handle_exception
    reraise(exc_type, exc_value, tb)
  File "c:\microblog\virtualenv\lib\site-packages\jinja2\_compat.py", line 37, in reraise
    raise value.with_traceback(tb)
  File "C:\microblog\app\templates\index.html", line 1, in top-level template code
    {% extends "base.html" %}
  File "C:\microblog\app\templates\base.html", line 33, in top-level template code
    {% block content %}{% endblock %}
  File "C:\microblog\app\templates\index.html", line 26, in block "content"
    {% include '_post.html' %}
  File "C:\microblog\app\templates\_post.html", line 3, in top-level template code
    <td><img src="{{ user.avatar(36) }}"></td>
  File "c:\microblog\virtualenv\lib\site-packages\jinja2\environment.py", line 430, in getattr
    return getattr(obj, attribute)
jinja2.exceptions.UndefinedError: 'user' is undefined
2018-07-15 21:26:55,586 INFO: Microblog startup [in C:\microblog\app\__init__.py:71]
2018-07-15 21:45:49,043 INFO: Microblog startup [in C:\microblog\app\__init__.py:71]
2018-07-15 22:07:00,483 INFO: Microblog startup [in C:\microblog\app\__init__.py:71]
2018-07-15 22:07:15,710 INFO: Microblog startup [in C:\microblog\app\__init__.py:71]
2018-07-15 22:07:44,315 INFO: Microblog startup [in C:\microblog\app\__init__.py:71]
2018-07-15 22:11:10,499 INFO: Microblog startup [in C:\microblog\app\__init__.py:71]
2018-07-15 22:11:34,184 ERROR: Exception on /user/saswatlevin/ [GET] [in c:\microblog\virtualenv\lib\site-packages\flask\app.py:1761]
Traceback (most recent call last):
  File "c:\microblog\virtualenv\lib\site-packages\flask\app.py", line 2292, in wsgi_app
    response = self.full_dispatch_request()
  File "c:\microblog\virtualenv\lib\site-packages\flask\app.py", line 1815, in full_dispatch_request
    rv = self.handle_user_exception(e)
  File "c:\microblog\virtualenv\lib\site-packages\flask\app.py", line 1718, in handle_user_exception
    reraise(exc_type, exc_value, tb)
  File "c:\microblog\virtualenv\lib\site-packages\flask\_compat.py", line 35, in reraise
    raise value
  File "c:\microblog\virtualenv\lib\site-packages\flask\app.py", line 1813, in full_dispatch_request
    rv = self.dispatch_request()
  File "c:\microblog\virtualenv\lib\site-packages\flask\app.py", line 1799, in dispatch_request
    return self.view_functions[rule.endpoint](**req.view_args)
  File "c:\microblog\virtualenv\lib\site-packages\flask_login\utils.py", line 261, in decorated_view
    return func(*args, **kwargs)
  File "C:\microblog\app\routes.py", line 144, in user
    page=request.get_args('page',1,type=int)
  File "c:\microblog\virtualenv\lib\site-packages\werkzeug\local.py", line 347, in __getattr__
    return getattr(self._get_current_object(), name)
AttributeError: 'Request' object has no attribute 'get_args'
2018-07-15 22:13:11,468 INFO: Microblog startup [in C:\microblog\app\__init__.py:71]
2018-07-15 22:14:36,637 INFO: Microblog startup [in C:\microblog\app\__init__.py:71]
2018-07-15 22:21:30,759 INFO: Microblog startup [in C:\microblog\app\__init__.py:71]
2018-07-15 22:21:49,499 ERROR: Exception on / [GET] [in c:\microblog\virtualenv\lib\site-packages\flask\app.py:1761]
Traceback (most recent call last):
  File "c:\microblog\virtualenv\lib\site-packages\flask\app.py", line 2292, in wsgi_app
    response = self.full_dispatch_request()
  File "c:\microblog\virtualenv\lib\site-packages\flask\app.py", line 1815, in full_dispatch_request
    rv = self.handle_user_exception(e)
  File "c:\microblog\virtualenv\lib\site-packages\flask\app.py", line 1718, in handle_user_exception
    reraise(exc_type, exc_value, tb)
  File "c:\microblog\virtualenv\lib\site-packages\flask\_compat.py", line 35, in reraise
    raise value
  File "c:\microblog\virtualenv\lib\site-packages\flask\app.py", line 1813, in full_dispatch_request
    rv = self.dispatch_request()
  File "c:\microblog\virtualenv\lib\site-packages\flask\app.py", line 1799, in dispatch_request
    return self.view_functions[rule.endpoint](**req.view_args)
  File "c:\microblog\virtualenv\lib\site-packages\flask_login\utils.py", line 261, in decorated_view
    return func(*args, **kwargs)
  File "C:\microblog\app\routes.py", line 42, in index
    return render_template('index.html',title='Home',form=form,posts=posts.items,prev_url=prev_url,next_url=next_url)
  File "c:\microblog\virtualenv\lib\site-packages\flask\templating.py", line 135, in render_template
    context, ctx.app)
  File "c:\microblog\virtualenv\lib\site-packages\flask\templating.py", line 117, in _render
    rv = template.render(context)
  File "c:\microblog\virtualenv\lib\site-packages\jinja2\asyncsupport.py", line 76, in render
    return original_render(self, *args, **kwargs)
  File "c:\microblog\virtualenv\lib\site-packages\jinja2\environment.py", line 1008, in render
    return self.environment.handle_exception(exc_info, True)
  File "c:\microblog\virtualenv\lib\site-packages\jinja2\environment.py", line 780, in handle_exception
    reraise(exc_type, exc_value, tb)
  File "c:\microblog\virtualenv\lib\site-packages\jinja2\_compat.py", line 37, in reraise
    raise value.with_traceback(tb)
  File "C:\microblog\app\templates\index.html", line 1, in top-level template code
    {% extends "base.html" %}
  File "C:\microblog\app\templates\base.html", line 33, in top-level template code
    {% block content %}{% endblock %}
  File "C:\microblog\app\templates\index.html", line 26, in block "content"
    {% include '_post.html' %}
  File "C:\microblog\app\templates\_post.html", line 3, in top-level template code
    <td><img src="{{ post.avatar(36) }}"></td>
jinja2.exceptions.UndefinedError: 'app.models.Post object' has no attribute 'avatar'
2018-07-15 22:52:27,835 INFO: Microblog startup [in C:\microblog\app\__init__.py:71]
2018-07-15 22:56:27,431 INFO: Microblog startup [in C:\microblog\app\__init__.py:71]
2018-07-15 22:58:49,340 INFO: Microblog startup [in C:\microblog\app\__init__.py:71]
2018-07-15 23:01:54,341 INFO: Microblog startup [in C:\microblog\app\__init__.py:71]
2018-07-15 23:04:47,378 INFO: Microblog startup [in C:\microblog\app\__init__.py:71]
