2018-07-15 10:48:39,910 ERROR: Exception on /index [GET] [in c:\microblog\virtualenv\lib\site-packages\flask\app.py:1761]
Traceback (most recent call last):
  File "c:\microblog\virtualenv\lib\site-packages\flask\app.py", line 2292, in wsgi_app
    response = self.full_dispatch_request()
  File "c:\microblog\virtualenv\lib\site-packages\flask\app.py", line 1815, in full_dispatch_request
    rv = self.handle_user_exception(e)
  File "c:\microblog\virtualenv\lib\site-packages\flask\app.py", line 1718, in handle_user_exception
    reraise(exc_type, exc_value, tb)
  File "c:\microblog\virtualenv\lib\site-packages\flask\_compat.py", line 35, in reraise
    raise value
  File "c:\microblog\virtualenv\lib\site-packages\flask\app.py", line 1813, in full_dispatch_request
    rv = self.dispatch_request()
  File "c:\microblog\virtualenv\lib\site-packages\flask\app.py", line 1799, in dispatch_request
    return self.view_functions[rule.endpoint](**req.view_args)
  File "c:\microblog\virtualenv\lib\site-packages\flask_login\utils.py", line 261, in decorated_view
    return func(*args, **kwargs)
  File "C:\microblog\app\routes.py", line 205, in index
    posts=current_user.followed_posts().all()
  File "C:\microblog\app\models.py", line 61, in followed_posts
    own=Post.query.join(followers.followed_id==self.id)
AttributeError: 'Table' object has no attribute 'followed_id'
2018-07-15 10:48:41,337 ERROR: Exception on /index [GET] [in c:\microblog\virtualenv\lib\site-packages\flask\app.py:1761]
Traceback (most recent call last):
  File "c:\microblog\virtualenv\lib\site-packages\flask\app.py", line 2292, in wsgi_app
    response = self.full_dispatch_request()
  File "c:\microblog\virtualenv\lib\site-packages\flask\app.py", line 1815, in full_dispatch_request
    rv = self.handle_user_exception(e)
  File "c:\microblog\virtualenv\lib\site-packages\flask\app.py", line 1718, in handle_user_exception
    reraise(exc_type, exc_value, tb)
  File "c:\microblog\virtualenv\lib\site-packages\flask\_compat.py", line 35, in reraise
    raise value
  File "c:\microblog\virtualenv\lib\site-packages\flask\app.py", line 1813, in full_dispatch_request
    rv = self.dispatch_request()
  File "c:\microblog\virtualenv\lib\site-packages\flask\app.py", line 1799, in dispatch_request
    return self.view_functions[rule.endpoint](**req.view_args)
  File "c:\microblog\virtualenv\lib\site-packages\flask_login\utils.py", line 261, in decorated_view
    return func(*args, **kwargs)
  File "C:\microblog\app\routes.py", line 205, in index
    posts=current_user.followed_posts().all()
  File "C:\microblog\app\models.py", line 61, in followed_posts
    own=Post.query.join(followers.followed_id==self.id)
AttributeError: 'Table' object has no attribute 'followed_id'
2018-07-15 10:48:42,434 ERROR: Exception on /index [GET] [in c:\microblog\virtualenv\lib\site-packages\flask\app.py:1761]
Traceback (most recent call last):
  File "c:\microblog\virtualenv\lib\site-packages\flask\app.py", line 2292, in wsgi_app
    response = self.full_dispatch_request()
  File "c:\microblog\virtualenv\lib\site-packages\flask\app.py", line 1815, in full_dispatch_request
    rv = self.handle_user_exception(e)
  File "c:\microblog\virtualenv\lib\site-packages\flask\app.py", line 1718, in handle_user_exception
    reraise(exc_type, exc_value, tb)
  File "c:\microblog\virtualenv\lib\site-packages\flask\_compat.py", line 35, in reraise
    raise value
  File "c:\microblog\virtualenv\lib\site-packages\flask\app.py", line 1813, in full_dispatch_request
    rv = self.dispatch_request()
  File "c:\microblog\virtualenv\lib\site-packages\flask\app.py", line 1799, in dispatch_request
    return self.view_functions[rule.endpoint](**req.view_args)
  File "c:\microblog\virtualenv\lib\site-packages\flask_login\utils.py", line 261, in decorated_view
    return func(*args, **kwargs)
  File "C:\microblog\app\routes.py", line 205, in index
    posts=current_user.followed_posts().all()
  File "C:\microblog\app\models.py", line 61, in followed_posts
    own=Post.query.join(followers.followed_id==self.id)
AttributeError: 'Table' object has no attribute 'followed_id'
2018-07-15 10:54:43,062 INFO: Microblog startup [in C:\microblog\app\__init__.py:71]
2018-07-15 11:03:39,048 INFO: Microblog startup [in C:\microblog\app\__init__.py:71]
2018-07-15 11:30:11,749 INFO: Microblog startup [in C:\microblog\app\__init__.py:71]
2018-07-15 11:38:53,305 INFO: Microblog startup [in C:\microblog\app\__init__.py:71]
2018-07-15 11:44:29,608 INFO: Microblog startup [in C:\microblog\app\__init__.py:71]
2018-07-15 11:44:44,677 ERROR: Exception on /index [GET] [in c:\microblog\virtualenv\lib\site-packages\flask\app.py:1761]
Traceback (most recent call last):
  File "c:\microblog\virtualenv\lib\site-packages\flask\app.py", line 2292, in wsgi_app
    response = self.full_dispatch_request()
  File "c:\microblog\virtualenv\lib\site-packages\flask\app.py", line 1815, in full_dispatch_request
    rv = self.handle_user_exception(e)
  File "c:\microblog\virtualenv\lib\site-packages\flask\app.py", line 1718, in handle_user_exception
    reraise(exc_type, exc_value, tb)
  File "c:\microblog\virtualenv\lib\site-packages\flask\_compat.py", line 35, in reraise
    raise value
  File "c:\microblog\virtualenv\lib\site-packages\flask\app.py", line 1813, in full_dispatch_request
    rv = self.dispatch_request()
  File "c:\microblog\virtualenv\lib\site-packages\flask\app.py", line 1799, in dispatch_request
    return self.view_functions[rule.endpoint](**req.view_args)
  File "c:\microblog\virtualenv\lib\site-packages\flask_login\utils.py", line 261, in decorated_view
    return func(*args, **kwargs)
  File "C:\microblog\app\routes.py", line 188, in index
    return render_template('index.html',title='Home',form=form,posts=posts)
  File "c:\microblog\virtualenv\lib\site-packages\flask\templating.py", line 135, in render_template
    context, ctx.app)
  File "c:\microblog\virtualenv\lib\site-packages\flask\templating.py", line 117, in _render
    rv = template.render(context)
  File "c:\microblog\virtualenv\lib\site-packages\jinja2\asyncsupport.py", line 76, in render
    return original_render(self, *args, **kwargs)
  File "c:\microblog\virtualenv\lib\site-packages\jinja2\environment.py", line 1008, in render
    return self.environment.handle_exception(exc_info, True)
  File "c:\microblog\virtualenv\lib\site-packages\jinja2\environment.py", line 780, in handle_exception
    reraise(exc_type, exc_value, tb)
  File "c:\microblog\virtualenv\lib\site-packages\jinja2\_compat.py", line 37, in reraise
    raise value.with_traceback(tb)
  File "C:\microblog\app\templates\index.html", line 1, in top-level template code
    {% extends "base.html" %}
  File "C:\microblog\app\templates\base.html", line 16, in top-level template code
    <a href="{{ url_for('user', username=current_user.username) }}">Profile</a>
  File "c:\microblog\virtualenv\lib\site-packages\flask\helpers.py", line 356, in url_for
    return appctx.app.handle_url_build_error(error, endpoint, values)
  File "c:\microblog\virtualenv\lib\site-packages\flask\app.py", line 2061, in handle_url_build_error
    reraise(exc_type, exc_value, tb)
  File "c:\microblog\virtualenv\lib\site-packages\flask\_compat.py", line 35, in reraise
    raise value
  File "c:\microblog\virtualenv\lib\site-packages\flask\helpers.py", line 345, in url_for
    force_external=external)
  File "c:\microblog\virtualenv\lib\site-packages\werkzeug\routing.py", line 1776, in build
    raise BuildError(endpoint, values, method, self)
werkzeug.routing.BuildError: Could not build url for endpoint 'user' with values ['username']. Did you mean 'follow_user' instead?
2018-07-15 11:48:21,965 INFO: Microblog startup [in C:\microblog\app\__init__.py:71]
2018-07-15 11:48:41,168 ERROR: Exception on /user/saswatlevin/ [GET] [in c:\microblog\virtualenv\lib\site-packages\flask\app.py:1761]
Traceback (most recent call last):
  File "c:\microblog\virtualenv\lib\site-packages\flask\app.py", line 2292, in wsgi_app
    response = self.full_dispatch_request()
  File "c:\microblog\virtualenv\lib\site-packages\flask\app.py", line 1815, in full_dispatch_request
    rv = self.handle_user_exception(e)
  File "c:\microblog\virtualenv\lib\site-packages\flask\app.py", line 1718, in handle_user_exception
    reraise(exc_type, exc_value, tb)
  File "c:\microblog\virtualenv\lib\site-packages\flask\_compat.py", line 35, in reraise
    raise value
  File "c:\microblog\virtualenv\lib\site-packages\flask\app.py", line 1813, in full_dispatch_request
    rv = self.dispatch_request()
  File "c:\microblog\virtualenv\lib\site-packages\flask\app.py", line 1799, in dispatch_request
    return self.view_functions[rule.endpoint](**req.view_args)
  File "c:\microblog\virtualenv\lib\site-packages\flask_login\utils.py", line 261, in decorated_view
    return func(*args, **kwargs)
TypeError: user() got an unexpected keyword argument 'username'
2018-07-15 11:50:26,922 INFO: Microblog startup [in C:\microblog\app\__init__.py:71]
