2018-07-15 11:50:42,227 ERROR: Exception on /user/saswatlevin/ [GET] [in c:\microblog\virtualenv\lib\site-packages\flask\app.py:1761]
Traceback (most recent call last):
  File "c:\microblog\virtualenv\lib\site-packages\flask\app.py", line 2292, in wsgi_app
    response = self.full_dispatch_request()
  File "c:\microblog\virtualenv\lib\site-packages\flask\app.py", line 1815, in full_dispatch_request
    rv = self.handle_user_exception(e)
  File "c:\microblog\virtualenv\lib\site-packages\flask\app.py", line 1718, in handle_user_exception
    reraise(exc_type, exc_value, tb)
  File "c:\microblog\virtualenv\lib\site-packages\flask\_compat.py", line 35, in reraise
    raise value
  File "c:\microblog\virtualenv\lib\site-packages\flask\app.py", line 1813, in full_dispatch_request
    rv = self.dispatch_request()
  File "c:\microblog\virtualenv\lib\site-packages\flask\app.py", line 1799, in dispatch_request
    return self.view_functions[rule.endpoint](**req.view_args)
  File "c:\microblog\virtualenv\lib\site-packages\flask_login\utils.py", line 261, in decorated_view
    return func(*args, **kwargs)
  File "C:\microblog\app\routes.py", line 124, in user
    user=User.guery.filter_by(username=username).first_or_404()
AttributeError: type object 'User' has no attribute 'guery'
2018-07-15 11:52:07,803 INFO: Microblog startup [in C:\microblog\app\__init__.py:71]
2018-07-15 11:52:25,034 INFO: Microblog startup [in C:\microblog\app\__init__.py:71]
2018-07-15 11:52:50,447 ERROR: Exception on /user/saswatlevin/ [GET] [in c:\microblog\virtualenv\lib\site-packages\flask\app.py:1761]
Traceback (most recent call last):
  File "c:\microblog\virtualenv\lib\site-packages\flask\app.py", line 2292, in wsgi_app
    response = self.full_dispatch_request()
  File "c:\microblog\virtualenv\lib\site-packages\flask\app.py", line 1815, in full_dispatch_request
    rv = self.handle_user_exception(e)
  File "c:\microblog\virtualenv\lib\site-packages\flask\app.py", line 1718, in handle_user_exception
    reraise(exc_type, exc_value, tb)
  File "c:\microblog\virtualenv\lib\site-packages\flask\_compat.py", line 35, in reraise
    raise value
  File "c:\microblog\virtualenv\lib\site-packages\flask\app.py", line 1813, in full_dispatch_request
    rv = self.dispatch_request()
  File "c:\microblog\virtualenv\lib\site-packages\flask\app.py", line 1799, in dispatch_request
    return self.view_functions[rule.endpoint](**req.view_args)
  File "c:\microblog\virtualenv\lib\site-packages\flask_login\utils.py", line 261, in decorated_view
    return func(*args, **kwargs)
  File "C:\microblog\app\routes.py", line 124, in user
    user=User.guery.filter_by(username=username).first_or_404()
AttributeError: type object 'User' has no attribute 'guery'
2018-07-15 11:53:39,966 INFO: Microblog startup [in C:\microblog\app\__init__.py:71]
2018-07-15 13:54:00,565 INFO: Microblog startup [in C:\microblog\app\__init__.py:71]
2018-07-15 14:28:38,790 INFO: Microblog startup [in C:\microblog\app\__init__.py:71]
2018-07-15 14:28:44,656 ERROR: Exception on / [GET] [in c:\microblog\virtualenv\lib\site-packages\flask\app.py:1761]
Traceback (most recent call last):
  File "c:\microblog\virtualenv\lib\site-packages\flask\app.py", line 2292, in wsgi_app
    response = self.full_dispatch_request()
  File "c:\microblog\virtualenv\lib\site-packages\flask\app.py", line 1815, in full_dispatch_request
    rv = self.handle_user_exception(e)
  File "c:\microblog\virtualenv\lib\site-packages\flask\app.py", line 1718, in handle_user_exception
    reraise(exc_type, exc_value, tb)
  File "c:\microblog\virtualenv\lib\site-packages\flask\_compat.py", line 35, in reraise
    raise value
  File "c:\microblog\virtualenv\lib\site-packages\flask\app.py", line 1813, in full_dispatch_request
    rv = self.dispatch_request()
  File "c:\microblog\virtualenv\lib\site-packages\flask\app.py", line 1799, in dispatch_request
    return self.view_functions[rule.endpoint](**req.view_args)
  File "c:\microblog\virtualenv\lib\site-packages\flask_login\utils.py", line 261, in decorated_view
    return func(*args, **kwargs)
  File "C:\microblog\app\routes.py", line 192, in index
    return render_template('index.html',title='Home',form=form,posts=posts)
  File "c:\microblog\virtualenv\lib\site-packages\flask\templating.py", line 135, in render_template
    context, ctx.app)
  File "c:\microblog\virtualenv\lib\site-packages\flask\templating.py", line 117, in _render
    rv = template.render(context)
  File "c:\microblog\virtualenv\lib\site-packages\jinja2\asyncsupport.py", line 76, in render
    return original_render(self, *args, **kwargs)
  File "c:\microblog\virtualenv\lib\site-packages\jinja2\environment.py", line 1008, in render
    return self.environment.handle_exception(exc_info, True)
  File "c:\microblog\virtualenv\lib\site-packages\jinja2\environment.py", line 780, in handle_exception
    reraise(exc_type, exc_value, tb)
  File "c:\microblog\virtualenv\lib\site-packages\jinja2\_compat.py", line 37, in reraise
    raise value.with_traceback(tb)
  File "C:\microblog\app\templates\index.html", line 1, in top-level template code
    {% extends "base.html" %}
  File "C:\microblog\app\templates\base.html", line 17, in top-level template code
    <a href="{{url_for('explore')}}">Explore</a>
  File "c:\microblog\virtualenv\lib\site-packages\flask\helpers.py", line 356, in url_for
    return appctx.app.handle_url_build_error(error, endpoint, values)
  File "c:\microblog\virtualenv\lib\site-packages\flask\app.py", line 2061, in handle_url_build_error
    reraise(exc_type, exc_value, tb)
  File "c:\microblog\virtualenv\lib\site-packages\flask\_compat.py", line 35, in reraise
    raise value
  File "c:\microblog\virtualenv\lib\site-packages\flask\helpers.py", line 345, in url_for
    force_external=external)
  File "c:\microblog\virtualenv\lib\site-packages\werkzeug\routing.py", line 1776, in build
    raise BuildError(endpoint, values, method, self)
werkzeug.routing.BuildError: Could not build url for endpoint 'explore'. Did you mean 'edit_profile' instead?
2018-07-15 14:31:36,113 INFO: Microblog startup [in C:\microblog\app\__init__.py:71]
2018-07-15 14:32:48,502 INFO: Microblog startup [in C:\microblog\app\__init__.py:71]
2018-07-15 14:32:55,969 INFO: Microblog startup [in C:\microblog\app\__init__.py:71]
2018-07-15 14:33:04,136 ERROR: Exception on / [GET] [in c:\microblog\virtualenv\lib\site-packages\flask\app.py:1761]
Traceback (most recent call last):
  File "c:\microblog\virtualenv\lib\site-packages\flask\app.py", line 2292, in wsgi_app
    response = self.full_dispatch_request()
  File "c:\microblog\virtualenv\lib\site-packages\flask\app.py", line 1815, in full_dispatch_request
    rv = self.handle_user_exception(e)
  File "c:\microblog\virtualenv\lib\site-packages\flask\app.py", line 1718, in handle_user_exception
    reraise(exc_type, exc_value, tb)
  File "c:\microblog\virtualenv\lib\site-packages\flask\_compat.py", line 35, in reraise
    raise value
  File "c:\microblog\virtualenv\lib\site-packages\flask\app.py", line 1813, in full_dispatch_request
    rv = self.dispatch_request()
  File "c:\microblog\virtualenv\lib\site-packages\flask\app.py", line 1799, in dispatch_request
    return self.view_functions[rule.endpoint](**req.view_args)
  File "c:\microblog\virtualenv\lib\site-packages\flask_login\utils.py", line 261, in decorated_view
    return func(*args, **kwargs)
  File "C:\microblog\app\routes.py", line 31, in index
    return render_template('index.html',title='Home',form=form,posts=posts)
  File "c:\microblog\virtualenv\lib\site-packages\flask\templating.py", line 135, in render_template
    context, ctx.app)
  File "c:\microblog\virtualenv\lib\site-packages\flask\templating.py", line 117, in _render
    rv = template.render(context)
  File "c:\microblog\virtualenv\lib\site-packages\jinja2\asyncsupport.py", line 76, in render
    return original_render(self, *args, **kwargs)
  File "c:\microblog\virtualenv\lib\site-packages\jinja2\environment.py", line 1008, in render
    return self.environment.handle_exception(exc_info, True)
  File "c:\microblog\virtualenv\lib\site-packages\jinja2\environment.py", line 780, in handle_exception
    reraise(exc_type, exc_value, tb)
  File "c:\microblog\virtualenv\lib\site-packages\jinja2\_compat.py", line 37, in reraise
    raise value.with_traceback(tb)
  File "C:\microblog\app\templates\index.html", line 1, in top-level template code
    {% extends "base.html" %}
  File "C:\microblog\app\templates\base.html", line 17, in top-level template code
    <a href="{{url_for('explore')}}">Explore</a>
  File "c:\microblog\virtualenv\lib\site-packages\flask\helpers.py", line 356, in url_for
    return appctx.app.handle_url_build_error(error, endpoint, values)
  File "c:\microblog\virtualenv\lib\site-packages\flask\app.py", line 2061, in handle_url_build_error
    reraise(exc_type, exc_value, tb)
  File "c:\microblog\virtualenv\lib\site-packages\flask\_compat.py", line 35, in reraise
    raise value
  File "c:\microblog\virtualenv\lib\site-packages\flask\helpers.py", line 345, in url_for
    force_external=external)
  File "c:\microblog\virtualenv\lib\site-packages\werkzeug\routing.py", line 1776, in build
    raise BuildError(endpoint, values, method, self)
werkzeug.routing.BuildError: Could not build url for endpoint 'explore'. Did you mean 'edit_profile' instead?
2018-07-15 14:35:25,259 INFO: Microblog startup [in C:\microblog\app\__init__.py:71]
